[2025-05-15T04:51:52.067+0000] {taskinstance.py:1956} INFO - Dependencies all met for dep_context=non-requeueable deps ti=<TaskInstance: daily_weather_report.fetch_and_store_weather scheduled__2025-05-14T00:00:00+00:00 [queued]>
[2025-05-15T04:51:52.099+0000] {taskinstance.py:1956} INFO - Dependencies all met for dep_context=requeueable deps ti=<TaskInstance: daily_weather_report.fetch_and_store_weather scheduled__2025-05-14T00:00:00+00:00 [queued]>
[2025-05-15T04:51:52.101+0000] {taskinstance.py:2170} INFO - Starting attempt 2 of 2
[2025-05-15T04:51:52.152+0000] {taskinstance.py:2191} INFO - Executing <Task(PythonOperator): fetch_and_store_weather> on 2025-05-14 00:00:00+00:00
[2025-05-15T04:51:52.163+0000] {standard_task_runner.py:60} INFO - Started process 1988 to run task
[2025-05-15T04:51:52.173+0000] {standard_task_runner.py:87} INFO - Running: ['***', 'tasks', 'run', 'daily_weather_report', 'fetch_and_store_weather', 'scheduled__2025-05-14T00:00:00+00:00', '--job-id', '5', '--raw', '--subdir', 'DAGS_FOLDER/daily_weather_dag.py', '--cfg-path', '/tmp/tmpy3744jf3']
[2025-05-15T04:51:52.185+0000] {standard_task_runner.py:88} INFO - Job 5: Subtask fetch_and_store_weather
[2025-05-15T04:51:52.234+0000] {logging_mixin.py:188} WARNING - /home/***/.local/lib/python3.8/site-packages/***/settings.py:194 DeprecationWarning: The sql_alchemy_conn option in [core] has been moved to the sql_alchemy_conn option in [database] - the old setting has been used, but please update your config.
[2025-05-15T04:51:52.317+0000] {task_command.py:423} INFO - Running <TaskInstance: daily_weather_report.fetch_and_store_weather scheduled__2025-05-14T00:00:00+00:00 [running]> on host 80d173fc4dec
[2025-05-15T04:51:52.515+0000] {taskinstance.py:2480} INFO - Exporting env vars: AIRFLOW_CTX_DAG_OWNER='***' AIRFLOW_CTX_DAG_ID='daily_weather_report' AIRFLOW_CTX_TASK_ID='fetch_and_store_weather' AIRFLOW_CTX_EXECUTION_DATE='2025-05-14T00:00:00+00:00' AIRFLOW_CTX_TRY_NUMBER='2' AIRFLOW_CTX_DAG_RUN_ID='scheduled__2025-05-14T00:00:00+00:00'
[2025-05-15T04:51:56.584+0000] {logging_mixin.py:188} INFO - Successfully fetched weather data for Hyderabad
[2025-05-15T04:52:00.466+0000] {logging_mixin.py:188} INFO - Error inserting weather data: could not translate host name "postgres" to address: Name or service not known
[2025-05-15T04:52:00.469+0000] {taskinstance.py:2698} ERROR - Task failed with exception
Traceback (most recent call last):
  File "/opt/airflow/dags/db_writer.py", line 55, in insert_weather_data
    conn = get_db_connection()
  File "/opt/airflow/dags/db_writer.py", line 16, in get_db_connection
    conn = psycopg2.connect(
  File "/home/airflow/.local/lib/python3.8/site-packages/psycopg2/__init__.py", line 122, in connect
    conn = _connect(dsn, connection_factory=connection_factory, **kwasync)
psycopg2.OperationalError: could not translate host name "postgres" to address: Name or service not known


During handling of the above exception, another exception occurred:

Traceback (most recent call last):
  File "/home/airflow/.local/lib/python3.8/site-packages/airflow/models/taskinstance.py", line 433, in _execute_task
    result = execute_callable(context=context, **execute_callable_kwargs)
  File "/home/airflow/.local/lib/python3.8/site-packages/airflow/operators/python.py", line 199, in execute
    return_value = self.execute_callable()
  File "/home/airflow/.local/lib/python3.8/site-packages/airflow/operators/python.py", line 216, in execute_callable
    return self.python_callable(*self.op_args, **self.op_kwargs)
  File "/opt/airflow/dags/daily_weather_dag.py", line 15, in fetch_and_store
    insert_weather_data(data)
  File "/opt/airflow/dags/db_writer.py", line 81, in insert_weather_data
    if conn:
UnboundLocalError: local variable 'conn' referenced before assignment
[2025-05-15T04:52:00.533+0000] {taskinstance.py:1138} INFO - Marking task as FAILED. dag_id=daily_weather_report, task_id=fetch_and_store_weather, execution_date=20250514T000000, start_date=20250515T045152, end_date=20250515T045200
[2025-05-15T04:52:00.620+0000] {standard_task_runner.py:107} ERROR - Failed to execute job 5 for task fetch_and_store_weather (local variable 'conn' referenced before assignment; 1988)
[2025-05-15T04:52:00.645+0000] {local_task_job_runner.py:234} INFO - Task exited with return code 1
[2025-05-15T04:52:00.673+0000] {taskinstance.py:3280} INFO - 0 downstream tasks scheduled from follow-on schedule check
[2025-05-15T05:25:56.276+0000] {taskinstance.py:1956} INFO - Dependencies all met for dep_context=non-requeueable deps ti=<TaskInstance: daily_weather_report.fetch_and_store_weather scheduled__2025-05-14T00:00:00+00:00 [queued]>
[2025-05-15T05:25:56.288+0000] {taskinstance.py:1956} INFO - Dependencies all met for dep_context=requeueable deps ti=<TaskInstance: daily_weather_report.fetch_and_store_weather scheduled__2025-05-14T00:00:00+00:00 [queued]>
[2025-05-15T05:25:56.289+0000] {taskinstance.py:2170} INFO - Starting attempt 2 of 2
[2025-05-15T05:25:56.312+0000] {taskinstance.py:2191} INFO - Executing <Task(PythonOperator): fetch_and_store_weather> on 2025-05-14 00:00:00+00:00
[2025-05-15T05:25:56.316+0000] {standard_task_runner.py:60} INFO - Started process 755 to run task
[2025-05-15T05:25:56.319+0000] {standard_task_runner.py:87} INFO - Running: ['***', 'tasks', 'run', 'daily_weather_report', 'fetch_and_store_weather', 'scheduled__2025-05-14T00:00:00+00:00', '--job-id', '12', '--raw', '--subdir', 'DAGS_FOLDER/daily_weather_dag.py', '--cfg-path', '/tmp/tmparrss1m6']
[2025-05-15T05:25:56.322+0000] {standard_task_runner.py:88} INFO - Job 12: Subtask fetch_and_store_weather
[2025-05-15T05:25:56.342+0000] {logging_mixin.py:188} WARNING - /home/***/.local/lib/python3.8/site-packages/***/settings.py:194 DeprecationWarning: The sql_alchemy_conn option in [core] has been moved to the sql_alchemy_conn option in [database] - the old setting has been used, but please update your config.
[2025-05-15T05:25:56.380+0000] {task_command.py:423} INFO - Running <TaskInstance: daily_weather_report.fetch_and_store_weather scheduled__2025-05-14T00:00:00+00:00 [running]> on host 2158c1e84d48
[2025-05-15T05:25:56.462+0000] {taskinstance.py:2480} INFO - Exporting env vars: AIRFLOW_CTX_DAG_OWNER='***' AIRFLOW_CTX_DAG_ID='daily_weather_report' AIRFLOW_CTX_TASK_ID='fetch_and_store_weather' AIRFLOW_CTX_EXECUTION_DATE='2025-05-14T00:00:00+00:00' AIRFLOW_CTX_TRY_NUMBER='2' AIRFLOW_CTX_DAG_RUN_ID='scheduled__2025-05-14T00:00:00+00:00'
[2025-05-15T05:25:56.602+0000] {logging_mixin.py:188} INFO - Successfully fetched weather data for Hyderabad
[2025-05-15T05:26:00.352+0000] {logging_mixin.py:188} INFO - Error inserting weather data: could not translate host name "postgres" to address: Name or service not known
[2025-05-15T05:26:00.354+0000] {taskinstance.py:2698} ERROR - Task failed with exception
Traceback (most recent call last):
  File "/opt/airflow/dags/db_writer.py", line 55, in insert_weather_data
    conn = get_db_connection()
  File "/opt/airflow/dags/db_writer.py", line 16, in get_db_connection
    conn = psycopg2.connect(
  File "/home/airflow/.local/lib/python3.8/site-packages/psycopg2/__init__.py", line 122, in connect
    conn = _connect(dsn, connection_factory=connection_factory, **kwasync)
psycopg2.OperationalError: could not translate host name "postgres" to address: Name or service not known


During handling of the above exception, another exception occurred:

Traceback (most recent call last):
  File "/home/airflow/.local/lib/python3.8/site-packages/airflow/models/taskinstance.py", line 433, in _execute_task
    result = execute_callable(context=context, **execute_callable_kwargs)
  File "/home/airflow/.local/lib/python3.8/site-packages/airflow/operators/python.py", line 199, in execute
    return_value = self.execute_callable()
  File "/home/airflow/.local/lib/python3.8/site-packages/airflow/operators/python.py", line 216, in execute_callable
    return self.python_callable(*self.op_args, **self.op_kwargs)
  File "/opt/airflow/dags/daily_weather_dag.py", line 15, in fetch_and_store
    insert_weather_data(data)
  File "/opt/airflow/dags/db_writer.py", line 81, in insert_weather_data
    if conn:
UnboundLocalError: local variable 'conn' referenced before assignment
[2025-05-15T05:26:00.368+0000] {taskinstance.py:1138} INFO - Marking task as FAILED. dag_id=daily_weather_report, task_id=fetch_and_store_weather, execution_date=20250514T000000, start_date=20250515T052556, end_date=20250515T052600
[2025-05-15T05:26:00.400+0000] {standard_task_runner.py:107} ERROR - Failed to execute job 12 for task fetch_and_store_weather (local variable 'conn' referenced before assignment; 755)
[2025-05-15T05:26:00.440+0000] {local_task_job_runner.py:234} INFO - Task exited with return code 1
[2025-05-15T05:26:00.473+0000] {taskinstance.py:3280} INFO - 0 downstream tasks scheduled from follow-on schedule check
