[2025-05-15T04:51:52.067+0000] {taskinstance.py:1956} INFO - Dependencies all met for dep_context=non-requeueable deps ti=<TaskInstance: daily_weather_report.fetch_and_store_weather manual__2025-05-15T04:46:44.613745+00:00 [queued]>
[2025-05-15T04:51:52.101+0000] {taskinstance.py:1956} INFO - Dependencies all met for dep_context=requeueable deps ti=<TaskInstance: daily_weather_report.fetch_and_store_weather manual__2025-05-15T04:46:44.613745+00:00 [queued]>
[2025-05-15T04:51:52.103+0000] {taskinstance.py:2170} INFO - Starting attempt 2 of 2
[2025-05-15T04:51:52.159+0000] {taskinstance.py:2191} INFO - Executing <Task(PythonOperator): fetch_and_store_weather> on 2025-05-15 04:46:44.613745+00:00
[2025-05-15T04:51:52.169+0000] {standard_task_runner.py:60} INFO - Started process 1989 to run task
[2025-05-15T04:51:52.182+0000] {standard_task_runner.py:87} INFO - Running: ['***', 'tasks', 'run', 'daily_weather_report', 'fetch_and_store_weather', 'manual__2025-05-15T04:46:44.613745+00:00', '--job-id', '4', '--raw', '--subdir', 'DAGS_FOLDER/daily_weather_dag.py', '--cfg-path', '/tmp/tmpb0i65sb7']
[2025-05-15T04:51:52.188+0000] {standard_task_runner.py:88} INFO - Job 4: Subtask fetch_and_store_weather
[2025-05-15T04:51:52.244+0000] {logging_mixin.py:188} WARNING - /home/***/.local/lib/python3.8/site-packages/***/settings.py:194 DeprecationWarning: The sql_alchemy_conn option in [core] has been moved to the sql_alchemy_conn option in [database] - the old setting has been used, but please update your config.
[2025-05-15T04:51:52.324+0000] {task_command.py:423} INFO - Running <TaskInstance: daily_weather_report.fetch_and_store_weather manual__2025-05-15T04:46:44.613745+00:00 [running]> on host 80d173fc4dec
[2025-05-15T04:51:52.509+0000] {taskinstance.py:2480} INFO - Exporting env vars: AIRFLOW_CTX_DAG_OWNER='***' AIRFLOW_CTX_DAG_ID='daily_weather_report' AIRFLOW_CTX_TASK_ID='fetch_and_store_weather' AIRFLOW_CTX_EXECUTION_DATE='2025-05-15T04:46:44.613745+00:00' AIRFLOW_CTX_TRY_NUMBER='2' AIRFLOW_CTX_DAG_RUN_ID='manual__2025-05-15T04:46:44.613745+00:00'
[2025-05-15T04:51:56.588+0000] {logging_mixin.py:188} INFO - Successfully fetched weather data for Hyderabad
[2025-05-15T04:52:00.466+0000] {logging_mixin.py:188} INFO - Error inserting weather data: could not translate host name "postgres" to address: Name or service not known
[2025-05-15T04:52:00.469+0000] {taskinstance.py:2698} ERROR - Task failed with exception
Traceback (most recent call last):
  File "/opt/airflow/dags/db_writer.py", line 55, in insert_weather_data
    conn = get_db_connection()
  File "/opt/airflow/dags/db_writer.py", line 16, in get_db_connection
    conn = psycopg2.connect(
  File "/home/airflow/.local/lib/python3.8/site-packages/psycopg2/__init__.py", line 122, in connect
    conn = _connect(dsn, connection_factory=connection_factory, **kwasync)
psycopg2.OperationalError: could not translate host name "postgres" to address: Name or service not known


During handling of the above exception, another exception occurred:

Traceback (most recent call last):
  File "/home/airflow/.local/lib/python3.8/site-packages/airflow/models/taskinstance.py", line 433, in _execute_task
    result = execute_callable(context=context, **execute_callable_kwargs)
  File "/home/airflow/.local/lib/python3.8/site-packages/airflow/operators/python.py", line 199, in execute
    return_value = self.execute_callable()
  File "/home/airflow/.local/lib/python3.8/site-packages/airflow/operators/python.py", line 216, in execute_callable
    return self.python_callable(*self.op_args, **self.op_kwargs)
  File "/opt/airflow/dags/daily_weather_dag.py", line 15, in fetch_and_store
    insert_weather_data(data)
  File "/opt/airflow/dags/db_writer.py", line 81, in insert_weather_data
    if conn:
UnboundLocalError: local variable 'conn' referenced before assignment
[2025-05-15T04:52:00.540+0000] {taskinstance.py:1138} INFO - Marking task as FAILED. dag_id=daily_weather_report, task_id=fetch_and_store_weather, execution_date=20250515T044644, start_date=20250515T045152, end_date=20250515T045200
[2025-05-15T04:52:00.623+0000] {standard_task_runner.py:107} ERROR - Failed to execute job 4 for task fetch_and_store_weather (local variable 'conn' referenced before assignment; 1989)
[2025-05-15T04:52:00.642+0000] {local_task_job_runner.py:234} INFO - Task exited with return code 1
[2025-05-15T04:52:00.671+0000] {taskinstance.py:3280} INFO - 0 downstream tasks scheduled from follow-on schedule check
